Workbook

Sheet Harvest # Summary
C1: Sport | E1: Personal Use | G1: Subsistence | I1: Personal-Use + Subsistence | P1: % by species | R1: Sport | T1: Personal Use + Sport
A2: Year | B2: Commercial | C2: Conservative | D2: Liberal | E2: Conservative | F2: Liberal | G2: Conservative | H2: Liberal | I2: Conservative | J2: Liberal | P2: Species | Q2: Commercial | R2: % Cons | S2: % Lib | T2: % Cons | U2: % Lib
A3: 2011 | B3: =Commercial!U3 -> 68008573 | C3: =Sport!M23 -> 526200.4 | D3: =Sport!N23 -> 778059.78 | E3: ='Personal Use'!M23 -> 278869.65 | F3: ='Personal Use'!N23 -> 552118.48 | G3: =Subsistence!M23 -> 20447.261 | H3: =Subsistence!N23 -> 29998.202 | I3: =SUM(E3,G3) -> 299316.91 | J3: =SUM(F3,H3) -> 582116.68 | P3: Chinook | Q3: =ROUND(Commercial!R3,1) -> 0.1 | R3: =ROUND(Sport!S3,1) -> 3.1 | S3: =ROUND(Sport!T3,1) -> 2.6 | T3: ='Personal Use + Subsistence'!R3 -> 0.1309935 | U3: ='Personal Use + Subsistence'!S3 -> 0.16127657
A4: 2012 | B4: =Commercial!U4 -> 30007942 | C4: =Sport!M24 -> 518052.19 | D4: =Sport!N24 -> 793957.96 | E4: ='Personal Use'!M24 -> 272649.59 | F4: ='Personal Use'!N24 -> 538785.2 | G4: =Subsistence!M24 -> 22511.956 | H4: =Subsistence!N24 -> 34867.981 | I4: =SUM(E4,G4) -> 295161.54 | J4: =SUM(F4,H4) -> 573653.18 | P4: Chum | Q4: =ROUND(Commercial!R4,1) -> 4.4 | R4: =ROUND(Sport!S4,1) -> 1.3 | S4: =ROUND(Sport!T4,1) -> 1 | T4: ='Personal Use + Subsistence'!R4 -> 0.19841682 | U4: ='Personal Use + Subsistence'!S4 -> 0.1363099
A5: 2013 | B5: =Commercial!U5 -> 1.127784e+08 | C5: =Sport!M25 -> 626498.73 | D5: =Sport!N25 -> 894565.02 | E5: ='Personal Use'!M25 -> 180802.66 | F5: ='Personal Use'!N25 -> 358093 | G5: =Subsistence!M25 -> 20725.446 | H5: =Subsistence!N25 -> 32274.732 | I5: =SUM(E5,G5) -> 201528.11 | J5: =SUM(F5,H5) -> 390367.73 | P5: Coho | Q5: =ROUND(Commercial!R5,1) -> 4.6 | R5: =ROUND(Sport!S5,1) -> 40.5 | S5: =ROUND(Sport!T5,1) -> 33.8 | T5: ='Personal Use + Subsistence'!R5 -> 1.0884649 | U5: ='Personal Use + Subsistence'!S5 -> 1.1900325
A6: 2014 | B6: =Commercial!U6 -> 48420061 | C6: =Sport!M26 -> 680064.98 | D6: =Sport!N26 -> 936853.66 | E6: ='Personal Use'!M26 -> 198311.88 | F6: ='Personal Use'!N26 -> 407550.35 | G6: =Subsistence!M26 -> 18771.856 | H6: =Subsistence!N26 -> 25890.913 | I6: =SUM(E6,G6) -> 217083.74 | J6: =SUM(F6,H6) -> 433441.26 | P6: Pink | Q6: =ROUND(Commercial!R6,1) -> 88.9 | R6: =ROUND(Sport!S6,1) -> 12.4 | S6: =ROUND(Sport!T6,1) -> 10.5 | T6: ='Personal Use + Subsistence'!R6 -> 0.56352442 | U6: ='Personal Use + Subsistence'!S6 -> 2.3463308
A7: 2015 | B7: =Commercial!U7 -> 54173018 | C7: =Sport!M27 -> 634498.53 | D7: =Sport!N27 -> 881453.7 | E7: ='Personal Use'!M27 -> 196739.1 | F7: ='Personal Use'!N27 -> 390139 | G7: =Subsistence!M27 -> 17365.583 | H7: =Subsistence!N27 -> 23292.056 | I7: =SUM(E7,G7) -> 214104.69 | J7: =SUM(F7,H7) -> 413431.06 | P7: Sockeye | Q7: =ROUND(Commercial!R7,1) -> 2.1 | R7: =ROUND(Sport!S7,1) -> 42.7 | S7: =ROUND(Sport!T7,1) -> 52.2 | T7: ='Personal Use + Subsistence'!R7 -> 98.0186 | U7: ='Personal Use + Subsistence'!S7 -> 96.16605
A8: 2016 | B8: =Commercial!U8 -> 24772014 | C8: =Sport!M28 -> 532082.57 | D8: =Sport!N28 -> 762070.85 | E8: ='Personal Use'!M28 -> 136030.26 | F8: ='Personal Use'!N28 -> 274799 | G8: =Subsistence!M28 -> 18318.466 | H8: =Subsistence!N28 -> 26121.458 | I8: =SUM(E8,G8) -> 154348.73 | J8: =SUM(F8,H8) -> 300920.46
A9: 2017 | B9: =Commercial!U9 -> 46848004 | C9: =Sport!M29 -> 619058.66 | D9: =Sport!N29 -> 824343.59 | E9: ='Personal Use'!M29 -> 153748.74 | F9: ='Personal Use'!N29 -> 309306.5 | G9: =Subsistence!M29 -> 16940.802 | H9: =Subsistence!N29 -> 26402.283 | I9: =SUM(E9,G9) -> 170689.54 | J9: =SUM(F9,H9) -> 335708.78
A10: 2018 | B10: =Commercial!U10 -> 15863084 | C10: =Sport!M30 -> 368462.81 | D10: =Sport!N30 -> 521255.13 | E10: ='Personal Use'!M30 -> 86349.201 | F10: ='Personal Use'!N30 -> 178685 | G10: =Subsistence!M30 -> 18676.859 | H10: =Subsistence!N30 -> 34245.833 | I10: =SUM(E10,G10) -> 105026.06 | J10: =SUM(F10,H10) -> 212930.83
A11: 2019 | B11: =Commercial!U11 -> 32386230 | C11: =Sport!M31 -> 632726.83 | D11: =Sport!N31 -> 916516.48 | E11: ='Personal Use'!M31 -> 171459.61 | F11: ='Personal Use'!N31 -> 340299.44 | G11: =Subsistence!M31 -> 20247.13 | H11: =Subsistence!N31 -> 35885.321 | I11: =SUM(E11,G11) -> 191706.74 | J11: =SUM(F11,H11) -> 376184.77
A12: 2020 | B12: =Commercial!U12 -> 13929623 | C12: =Sport!M32 -> 375184.16 | D12: =Sport!N32 -> 547461.87 | E12: ='Personal Use'!M32 -> 133870.67 | F12: ='Personal Use'!N32 -> 274896.4 | G12: =Subsistence!M32 -> 14767.799 | H12: =Subsistence!N32 -> 28278.945 | I12: =SUM(E12,G12) -> 148638.47 | J12: =SUM(F12,H12) -> 303175.35
A13: Average | B13: =AVERAGE(B3:B12) -> 44718694 | C13: =AVERAGE(C3:C12) -> 551282.99 | D13: =AVERAGE(D3:D12) -> 785653.8 | E13: =AVERAGE(E3:E12) -> 180883.14 | F13: =AVERAGE(F3:F12) -> 362467.24 | G13: =AVERAGE(G3:G12) -> 18877.316 | H13: =AVERAGE(H3:H12) -> 29725.772 | I13: =AVERAGE(I3:I12) -> 199760.45 | J13: =AVERAGE(J3:J12) -> 392193.01 | K13: =SUM(B13,D13,F13,F13,H13) -> 46259008
A14: Median | B14: =MEDIAN(B3:B12) -> 39617117 | C14: =MEDIAN(C3:C12) -> 575570.62 | D14: =MEDIAN(D3:D12) -> 809150.78 | E14: =MEDIAN(E3:E12) -> 176131.14 | F14: =MEDIAN(F3:F12) -> 349196.22 | G14: =MEDIAN(G3:G12) -> 18724.358 | H14: =MEDIAN(H3:H12) -> 29138.574 | I14: =MEDIAN(I3:I12) -> 196617.43 | J14: =MEDIAN(J3:J12) -> 383276.25
A15: Min | B15: =MIN(B3:B12) -> 13929623 | C15: =MIN(C3:C12) -> 368462.81 | D15: =MIN(D3:D12) -> 521255.13 | E15: =MIN(E3:E12) -> 86349.201 | F15: =MIN(F3:F12) -> 178685 | G15: =MIN(G3:G12) -> 14767.799 | H15: =MIN(H3:H12) -> 23292.056 | I15: =MIN(I3:I12) -> 105026.06 | J15: =MIN(J3:J12) -> 212930.83
A16: Max | B16: =MAX(B3:B12) -> 1.127784e+08 | C16: =MAX(C3:C12) -> 680064.98 | D16: =MAX(D3:D12) -> 936853.66 | E16: =MAX(E3:E12) -> 278869.65 | F16: =MAX(F3:F12) -> 552118.48 | G16: =MAX(G3:G12) -> 22511.956 | H16: =MAX(H3:H12) -> 35885.321 | I16: =MAX(I3:I12) -> 299316.91 | J16: =MAX(J3:J12) -> 582116.68
A17: StDev | B17: =_xlfn.STDEV.S(B3:B12) -> 29494141 | C17: =_xlfn.STDEV.S(C3:C12) -> 109000.39 | D17: =_xlfn.STDEV.S(D3:D12) -> 145238.29 | E17: =_xlfn.STDEV.S(E3:E12) -> 60149.178 | F17: =_xlfn.STDEV.S(F3:F12) -> 116581.26 | G17: =_xlfn.STDEV.S(G3:G12) -> 2217.4682 | H17: =_xlfn.STDEV.S(H3:H12) -> 4392.0829 | I17: =_xlfn.STDEV.S(I3:I12) -> 61537.794 | J17: =_xlfn.STDEV.S(J3:J12) -> 116900.28
A18: COV | B18: =B17/B13 -> 0.65954834 | C18: =C17/C13 -> 0.1977213 | D18: =D17/D13 -> 0.18486296 | E18: =E17/E13 -> 0.3325306 | F18: =F17/F13 -> 0.32163256 | G18: =G17/G13 -> 0.11746735 | H18: =H17/H13 -> 0.14775336 | I18: =I17/I13 -> 0.30805794 | J18: =J17/J13 -> 0.29806824

Sheet Harvest Statistics
B1: Commercial | F1: Sport | L1: Personal-Use + Subsistence
B2: Year | C2: Ex-Vessel Value US$ (CPI Corrected to 2020) | D2: # of 6-oz Servings | G2: Replacement Cost | I2: # of 6-oz Servings | M2: Replacement Cost | O2: # of 6-oz Servings
B3: 2011 | C3: 2.2179835e+08 | D3: 3.7405218e+08 | F3: Year | G3: Conservative | H3: Liberal | I3: Conservative | J3: Liberal | L3: Year | M3: Conservative | N3: Liberal | O3: Conservative | P3: Liberal
B4: 2012 | C4: 1.2794247e+08 | D4: 1.874733e+08 | F4: 2011 | G4: =Sport!M64 -> 46265540 | H4: =Sport!N64 -> 69998161 | I4: =Sport!M53 -> 4898554.4 | J4: =Sport!N53 -> 7202353.6 | L4: 2011 | M4: ='Personal Use + Subsistence'!N75 -> 24892044 | N4: ='Personal Use + Subsistence'!O75 -> 48438696 | O4: ='Personal Use + Subsistence'!N64 -> 2413981.9 | P4: ='Personal Use + Subsistence'!O64 -> 4700876.6
B5: 2013 | C5: 2.7661088e+08 | D5: 5.3744682e+08 | F5: 2012 | G5: =Sport!M65 -> 43623732 | H5: =Sport!N65 -> 65982999 | I5: =Sport!M54 -> 4658480.6 | J5: =Sport!N54 -> 6938832.8 | L5: 2012 | M5: ='Personal Use + Subsistence'!N76 -> 24479796 | N5: ='Personal Use + Subsistence'!O76 -> 47382734 | O5: ='Personal Use + Subsistence'!N65 -> 2375272.3 | P5: ='Personal Use + Subsistence'!O65 -> 4608464.2
B6: 2014 | C6: 1.3635355e+08 | D6: 2.7260034e+08 | F6: 2013 | G6: =Sport!M66 -> 51866308 | H6: =Sport!N66 -> 74649034 | I6: =Sport!M55 -> 5705114.4 | J6: =Sport!N55 -> 8016156.8 | L6: 2013 | M6: ='Personal Use + Subsistence'!N77 -> 16776202 | N6: ='Personal Use + Subsistence'!O77 -> 32231941 | O6: ='Personal Use + Subsistence'!N66 -> 1625944.6 | P6: ='Personal Use + Subsistence'!O66 -> 3138357.2
B7: 2015 | C7: 99375821 | D7: 2.9818021e+08 | F7: 2014 | G7: =Sport!M67 -> 60849098 | H7: =Sport!N67 -> 81524323 | I7: =Sport!M56 -> 6530217.3 | J7: =Sport!N56 -> 8710203.8 | L7: 2014 | M7: ='Personal Use + Subsistence'!N78 -> 17997228 | N7: ='Personal Use + Subsistence'!O78 -> 34820724 | O7: ='Personal Use + Subsistence'!N67 -> 1748601.3 | P7: ='Personal Use + Subsistence'!O67 -> 3439729.7
B8: 2016 | C8: 91678827 | D8: 1.6391939e+08 | F8: 2015 | G8: =Sport!M68 -> 54691092 | H8: =Sport!N68 -> 76424377 | I8: =Sport!M57 -> 5947608 | J8: =Sport!N57 -> 8156171 | L8: 2015 | M8: ='Personal Use + Subsistence'!N79 -> 17753769 | N8: ='Personal Use + Subsistence'!O79 -> 34064104 | O8: ='Personal Use + Subsistence'!N68 -> 1726569.1 | P8: ='Personal Use + Subsistence'!O68 -> 3324769.9
B9: 2017 | C9: 1.509843e+08 | D9: 2.7437398e+08 | F9: 2016 | G9: =Sport!M69 -> 45382011 | H9: =Sport!N69 -> 65627307 | I9: =Sport!M58 -> 4922964.1 | J9: =Sport!N58 -> 6944909.6 | L9: 2016 | M9: ='Personal Use + Subsistence'!N80 -> 12808205 | N9: ='Personal Use + Subsistence'!O80 -> 24670790 | O9: ='Personal Use + Subsistence'!N69 -> 1247819.9 | P9: ='Personal Use + Subsistence'!O69 -> 2418471.7
B10: 2018 | C10: 88161107 | D10: 1.1478108e+08 | F10: 2017 | G10: =Sport!M70 -> 52351938 | H10: =Sport!N70 -> 71906574 | I10: =Sport!M59 -> 5842320 | J10: =Sport!N59 -> 7762099.7 | L10: 2017 | M10: ='Personal Use + Subsistence'!N81 -> 14232641 | N10: ='Personal Use + Subsistence'!O81 -> 27732916 | O10: ='Personal Use + Subsistence'!N70 -> 1377957.4 | P10: ='Personal Use + Subsistence'!O70 -> 2697512.6
B11: 2019 | C11: 91778690 | D11: 1.9000917e+08 | F11: 2018 | G11: =Sport!M71 -> 29898778 | H11: =Sport!N71 -> 42311840 | I11: =Sport!M60 -> 3358581.8 | J11: =Sport!N60 -> 4702850.6 | L11: 2018 | M11: ='Personal Use + Subsistence'!N82 -> 8710060.6 | N11: ='Personal Use + Subsistence'!O82 -> 17046681 | O11: ='Personal Use + Subsistence'!N71 -> 850594.84 | P11: ='Personal Use + Subsistence'!O71 -> 1690057.6
B12: 2020 | C12: 43914566 | D12: 82524071 | F12: 2019 | G12: =Sport!M72 -> 50395469 | H12: =Sport!N72 -> 74462748 | I12: =Sport!M61 -> 5519230.1 | J12: =Sport!N61 -> 7941319.7 | L12: 2019 | M12: ='Personal Use + Subsistence'!N83 -> 15915497 | N12: ='Personal Use + Subsistence'!O83 -> 30959932 | O12: ='Personal Use + Subsistence'!N72 -> 1545297.4 | P12: ='Personal Use + Subsistence'!O72 -> 3015429.9
B13: Average | C13: =AVERAGE(C3:C12) -> 1.3285986e+08 | D13: =AVERAGE(D3:D12) -> 2.4953605e+08 | F13: 2020 | G13: =Sport!M73 -> 31009090 | H13: =Sport!N73 -> 44904350 | I13: =Sport!M62 -> 3357202.7 | J13: =Sport!N62 -> 4799760.9 | L13: 2020 | M13: ='Personal Use + Subsistence'!N84 -> 12311014 | N13: ='Personal Use + Subsistence'!O84 -> 24304876 | O13: ='Personal Use + Subsistence'!N73 -> 1196071.6 | P13: ='Personal Use + Subsistence'!O73 -> 2398024.4
B14: median | C14: =MEDIAN(C3:C12) -> 1.1365914e+08 | D14: =MEDIAN(D3:D12) -> 2.3130475e+08 | F14: Average | G14: =AVERAGE(G4:G13) -> 46633305 | H14: =AVERAGE(H4:H13) -> 66779171 | I14: =Sport!M63 -> 5074027.3 | J14: =Sport!N63 -> 7117465.9 | L14: Average | M14: =AVERAGE(M4:M13) -> 16587646 | N14: =AVERAGE(N4:N13) -> 32165339 | O14: =AVERAGE(O4:O13) -> 1610811 | P14: =AVERAGE(P4:P13) -> 3143169.4
F15: Median | G15: =MEDIAN(G4:G13) -> 48330504 | H15: =MEDIAN(H4:H13) -> 70952368 | I15: =MEDIAN(I4:I13) -> 5221097.1 | J15: =MEDIAN(J4:J13) -> 7482226.6 | L15: Median | M15: =MEDIAN(M4:M13) -> 16345849 | N15: =MEDIAN(N4:N13) -> 31595936 | O15: =MEDIAN(O4:O13) -> 1585621 | P15: =MEDIAN(P4:P13) -> 3076893.5
B16: Total Replacement value | C16: =SUM(C13,H14,N14) -> 2.3180437e+08
B17: total 6 oz servings | C17: =SUM(D13,J14,P14) -> 2.5979669e+08
C18: =C17*(6/16) -> 97423758
B19: total 1/4 lbs servings | C19: =C18/(4/16) -> 3.8969503e+08
C25: =46000000*4*0.5 -> 92000000
C26: =C25/(4/16) -> 368000000

Sheet CombinedRAW
A1: Forest | B1: Year | C1: Fishery | D1: Species | E1: Conservative | F1: Liberal | I1: Conservative | J1: (Multiple Items)
A2: Chugach | B2: =ChugachRAW!A2 -> 2011 | C2: =ChugachRAW!C2 -> Sport | D2: =ChugachRAW!D2 -> Chinook | E2: =ChugachRAW!F2 -> 0 | F2: =ChugachRAW!G2 -> 0 | I2: Liberal | J2: (Multiple Items)
A3: Chugach | B3: =ChugachRAW!A3 -> 2012 | C3: =ChugachRAW!C3 -> Sport | D3: =ChugachRAW!D3 -> Chinook | E3: =ChugachRAW!F3 -> 0 | F3: =ChugachRAW!G3 -> 0
A4: Chugach | B4: =ChugachRAW!A4 -> 2013 | C4: =ChugachRAW!C4 -> Sport | D4: =ChugachRAW!D4 -> Chinook | E4: =ChugachRAW!F4 -> 0 | F4: =ChugachRAW!G4 -> 0 | L4: Species | M4: Values
A5: Chugach | B5: =ChugachRAW!A5 -> 2014 | C5: =ChugachRAW!C5 -> Sport | D5: =ChugachRAW!D5 -> Chinook | E5: =ChugachRAW!F5 -> 0 | F5: =ChugachRAW!G5 -> 0 | L5: Chinook | M5: Chinook | N5: Chum | O5: Chum | P5: Coho | Q5: Coho | R5: Pink | S5: Pink | T5: Sockeye | U5: Sockeye | V5: (blank) | W5: (blank)
A6: Chugach | B6: =ChugachRAW!A6 -> 2015 | C6: =ChugachRAW!C6 -> Sport | D6: =ChugachRAW!D6 -> Chinook | E6: =ChugachRAW!F6 -> 0 | F6: =ChugachRAW!G6 -> 0 | I6: Fishery | J6: Forest | K6: Year | L6: Sum of Conservative | M6: Sum of Liberal | N6: Sum of Conservative | O6: Sum of Liberal | P6: Sum of Conservative | Q6: Sum of Liberal | R6: Sum of Conservative | S6: Sum of Liberal | T6: Sum of Conservative | U6: Sum of Liberal | V6: Sum of Conservative | W6: Sum of Liberal
A7: Chugach | B7: =ChugachRAW!A7 -> 2016 | C7: =ChugachRAW!C7 -> Sport | D7: =ChugachRAW!D7 -> Chinook | E7: =ChugachRAW!F7 -> 0 | F7: =ChugachRAW!G7 -> 0 | I7: Personal use | J7: Chugach | K7: 2011 | L7: 211.31 | M7: 1243 | P7: 1043.9 | Q7: 4745 | R7: 156.56 | S7: 3914 | T7: 274260.15 | U7: 537765
A8: Chugach | B8: =ChugachRAW!A8 -> 2017 | C8: =ChugachRAW!C8 -> Sport | D8: =ChugachRAW!D8 -> Chinook | E8: =ChugachRAW!F8 -> 0 | F8: =ChugachRAW!G8 -> 0 | I8: Personal use | J8: Chugach | K8: 2012 | L8: 6.8 | M8: 40 | P8: 881.76 | Q8: 4008 | R8: 150.8 | S8: 3770 | T8: 268765.92 | U8: 526992
A9: Chugach | B9: =ChugachRAW!A9 -> 2018 | C9: =ChugachRAW!C9 -> Sport | D9: =ChugachRAW!D9 -> Chinook | E9: =ChugachRAW!F9 -> 0 | F9: =ChugachRAW!G9 -> 0 | I9: Personal use | J9: Chugach | K9: 2013 | L9: 1.87 | M9: 11 | P9: 697.18 | Q9: 3169 | R9: 145 | S9: 3625 | T9: 177083.22 | U9: 347222
A10: Chugach | B10: =ChugachRAW!A10 -> 2019 | C10: =ChugachRAW!C10 -> Sport | D10: =ChugachRAW!D10 -> Chinook | E10: =ChugachRAW!F10 -> 0 | F10: =ChugachRAW!G10 -> 0 | I10: Personal use | J10: Chugach | K10: 2014 | P10: 1036.2 | Q10: 4710 | R10: 765.6 | S10: 19140 | T10: 193709.73 | U10: 379823
A11: Chugach | B11: =ChugachRAW!A11 -> 2020 | C11: =ChugachRAW!C11 -> Sport | D11: =ChugachRAW!D11 -> Chinook | E11: =ChugachRAW!F11 -> 0 | F11: =ChugachRAW!G11 -> 0 | I11: Personal use | J11: Chugach | K11: 2015 | L11: 11.22 | M11: 66 | P11: 913 | Q11: 4150 | R11: 165.88 | S11: 4147 | T11: 192541.32 | U11: 377532
A12: Chugach | B12: =ChugachRAW!A12 -> 2011 | C12: =ChugachRAW!C12 -> Sport | D12: =ChugachRAW!D12 -> Sockeye | E12: =ChugachRAW!F12 -> 362.15125 | F12: =ChugachRAW!G12 -> 646.69867 | I12: Personal use | J12: Chugach | K12: 2016 | L12: 108.46 | M12: 638 | P12: 720.94 | Q12: 3277 | R12: 313.36 | S12: 7834 | T12: 132119.07 | U12: 259057
A13: Chugach | B13: =ChugachRAW!A13 -> 2012 | C13: =ChugachRAW!C13 -> Sport | D13: =ChugachRAW!D13 -> Sockeye | E13: =ChugachRAW!F13 -> 396.83485 | F13: =ChugachRAW!G13 -> 708.63367 | I13: Personal use | J13: Chugach | K13: 2017 | L13: 202.98 | M13: 1194 | P13: 161.04 | Q13: 732 | R13: 318.48 | S13: 7962 | T13: 151494.99 | U13: 297049
A14: Chugach | B14: =ChugachRAW!A14 -> 2013 | C14: =ChugachRAW!C14 -> Sport | D14: =ChugachRAW!D14 -> Sockeye | E14: =ChugachRAW!F14 -> 305.00139 | F14: =ChugachRAW!G14 -> 544.64533 | I14: Personal use | J14: Chugach | K14: 2018 | L14: 1.19 | M14: 7 | P14: 116.38 | Q14: 529 | R14: 417.4 | S14: 10435 | T14: 84164.28 | U14: 165028
A15: Chugach | B15: =ChugachRAW!A15 -> 2014 | C15: =ChugachRAW!C15 -> Sport | D15: =ChugachRAW!D15 -> Sockeye | E15: =ChugachRAW!F15 -> 302.48064 | F15: =ChugachRAW!G15 -> 540.144 | I15: Personal use | J15: Chugach | K15: 2019 | L15: 5.1 | M15: 30 | P15: 214.94 | Q15: 977 | R15: 185.24 | S15: 4631 | T15: 169018.08 | U15: 331408
A16: Chugach | B16: =ChugachRAW!A16 -> 2015 | C16: =ChugachRAW!C16 -> Sport | D16: =ChugachRAW!D16 -> Sockeye | E16: =ChugachRAW!F16 -> 149.01936 | F16: =ChugachRAW!G16 -> 266.106 | I16: Personal use | J16: Chugach | K16: 2020 | L16: 3.91 | M16: 23 | P16: 225.06 | Q16: 1023 | R16: 544.88 | S16: 13622 | T16: 131510.64 | U16: 257864
A17: Chugach | B17: =ChugachRAW!A17 -> 2016 | C17: =ChugachRAW!C17 -> Sport | D17: =ChugachRAW!D17 -> Sockeye | E17: =ChugachRAW!F17 -> 71.30368 | F17: =ChugachRAW!G17 -> 127.328 | I17: Personal use | J17: Tongass | K17: 2011 | L17: 2.026963 | M17: 3.9259259 | N17: 263.87037 | O17: 278 | P17: 70.12536 | Q17: 127.55187 | R17: 786.85252 | S17: 1252 | T17: 2074.8538 | U17: 2790
A18: Chugach | B18: =ChugachRAW!A18 -> 2017 | C18: =ChugachRAW!C18 -> Sport | D18: =ChugachRAW!D18 -> Sockeye | E18: =ChugachRAW!F18 -> 300.0844 | F18: =ChugachRAW!G18 -> 535.865 | I18: Personal use | J18: Tongass | K18: 2012 | L18: 1.6213476 | M18: 3 | N18: 295.62069 | O18: 310 | P18: 63.59906 | Q18: 116.19886 | R18: 404.53163 | S18: 518 | T18: 2078.9323 | U18: 3028
A19: Chugach | B19: =ChugachRAW!A19 -> 2018 | C19: =ChugachRAW!C19 -> Sport | D19: =ChugachRAW!D19 -> Sockeye | E19: =ChugachRAW!F19 -> 383.95616 | F19: =ChugachRAW!G19 -> 685.636 | I19: Personal use | J19: Tongass | K19: 2013 | L19: 18.245132 | M19: 29 | N19: 344.47795 | O19: 370 | P19: 181.58129 | Q19: 309 | R19: 525.97909 | S19: 622 | T19: 1805.109 | U19: 2736
A20: Chugach | B20: =ChugachRAW!A20 -> 2019 | C20: =ChugachRAW!C20 -> Sport | D20: =ChugachRAW!D20 -> Sockeye | E20: =ChugachRAW!F20 -> 691.13259 | F20: =ChugachRAW!G20 -> 1234.1653 | I20: Personal use | J20: Tongass | K20: 2014 | L20: 16.124649 | M20: 27 | N20: 196.46413 | O20: 209 | P20: 102.30097 | Q20: 197.25452 | R20: 301.88911 | S20: 387 | T20: 2183.5697 | U20: 3057.0954
A21: Chugach | B21: =ChugachRAW!A21 -> 2020 | C21: =ChugachRAW!C21 -> Sport | D21: =ChugachRAW!D21 -> Sockeye | E21: =ChugachRAW!F21 -> 1127.5342 | F21: =ChugachRAW!G21 -> 2013.454 | I21: Personal use | J21: Tongass | K21: 2015 | L21: 25.216384 | M21: 41 | N21: 278.892 | O21: 286 | P21: 151.35648 | Q21: 285 | R21: 527.11595 | S21: 778 | T21: 2125.1029 | U21: 2854
A22: Chugach | B22: =ChugachRAW!A22 -> 2011 | C22: =ChugachRAW!C22 -> Sport | D22: =ChugachRAW!D22 -> Coho | E22: =ChugachRAW!F22 -> 10213.23 | F22: =ChugachRAW!G22 -> 16743 | I22: Personal use | J22: Tongass | K22: 2016 | L22: 27.544771 | M22: 57 | N22: 414.86846 | O22: 433 | P22: 105.35495 | Q22: 193 | R22: 622.79437 | S22: 906 | T22: 1597.8691 | U22: 2404
A23: Chugach | B23: =ChugachRAW!A23 -> 2012 | C23: =ChugachRAW!C23 -> Sport | D23: =ChugachRAW!D23 -> Coho | E23: =ChugachRAW!F23 -> 2653.5 | F23: =ChugachRAW!G23 -> 4350 | I23: Personal use | J23: Tongass | K23: 2017 | L23: 1.1112924 | M23: 2 | N23: 169.16432 | O23: 185 | P23: 4.8184447 | Q23: 9.5 | R23: 230.54416 | S23: 395 | T23: 1165.614 | U23: 1778
A24: Chugach | B24: =ChugachRAW!A24 -> 2013 | C24: =ChugachRAW!C24 -> Sport | D24: =ChugachRAW!D24 -> Coho | E24: =ChugachRAW!F24 -> 8976.15 | F24: =ChugachRAW!G24 -> 14715 | I24: Personal use | J24: Tongass | K24: 2018 | L24: 8.0361992 | M24: 24 | N24: 576.89734 | O24: 951 | P24: 171.35597 | Q24: 303 | R24: 187.7406 | S24: 270 | T24: 705.92063 | U24: 1138
A25: Chugach | B25: =ChugachRAW!A25 -> 2014 | C25: =ChugachRAW!C25 -> Sport | D25: =ChugachRAW!D25 -> Coho | E25: =ChugachRAW!F25 -> 4221.2925 | F25: =ChugachRAW!G25 -> 6920.1517 | I25: Personal use | J25: Tongass | K25: 2019 | L25: 17.319016 | M25: 89 | N25: 120.83231 | O25: 149.63 | P25: 299.46664 | Q25: 444.05065 | R25: 144.0325 | S25: 229.48358 | T25: 1454.6026 | U25: 2341.2796
A26: Chugach | B26: =ChugachRAW!A26 -> 2015 | C26: =ChugachRAW!C26 -> Sport | D26: =ChugachRAW!D26 -> Coho | E26: =ChugachRAW!F26 -> 11535.1 | F26: =ChugachRAW!G26 -> 18910 | I26: Personal use | J26: Tongass | K26: 2020 | L26: 12.467712 | M26: 27.3 | N26: 4.3970705 | O26: 4.8315 | P26: 202.28059 | Q26: 325.97184 | R26: 415.6745 | S26: 486.60251 | T26: 951.35837 | U26: 1519.6953
A27: Chugach | B27: =ChugachRAW!A27 -> 2016 | C27: =ChugachRAW!C27 -> Sport | D27: =ChugachRAW!D27 -> Coho | E27: =ChugachRAW!F27 -> 1633.58 | F27: =ChugachRAW!G27 -> 2678 | I27: Sport | J27: Chugach | K27: 2011 | L27: 1749.81 | M27: 10293 | N27: 95.738133 | O27: 188.17267 | P27: 46602.27 | Q27: 87555 | R27: 2724.3936 | S27: 6254.504 | T27: 240383.55 | U27: 434629.7
A28: Chugach | B28: =ChugachRAW!A28 -> 2017 | C28: =ChugachRAW!C28 -> Sport | D28: =ChugachRAW!D28 -> Coho | E28: =ChugachRAW!F28 -> 6900.93 | F28: =ChugachRAW!G28 -> 11313 | I28: Sport | J28: Chugach | K28: 2012 | L28: 206.04 | M28: 1212 | N28: 23.728 | O28: 382.16 | P28: 38631.04 | Q28: 68725 | R28: 3262.0224 | S28: 20284.38 | T28: 263796.37 | U28: 487280.63
... A46: Chugach | B46: =ChugachRAW!A46 -> 2015 | C46: =ChugachRAW!C46 -> Sport | D46: =ChugachRAW!D46 -> Chum | E46: =ChugachRAW!F46 -> 144.92613 | F46: =ChugachRAW!G46 -> 181.15767 | I46: Sport | J46: Tongass | K46: 2020 | L46: 11139.421 | M46: 11283.025 | N46: 3383.384 | O46: 3555.9691 | P46: 103242.68 | Q46: 106830.87 | R46: 48182.333 | S46: 49392.286 | T46: 6678.1241 | U46: 7141.6
A47: Chugach | B47: =ChugachRAW!A47 -> 2016 | C47: =ChugachRAW!C47 -> Sport | D47: =ChugachRAW!D47 -> Chum | E47: =ChugachRAW!F47 -> 5.8184 | F47: =ChugachRAW!G47 -> 7.273 | I47: Subsistence | J47: Chugach | K47: 2011 | N47: 28.539733 | O47: 35.674667 | P47: 913.65 | Q47: 1139 | R47: 12.6435 | S47: 14.048333 | T47: 1838.7519 | U47: 3917.2713
A48: Chugach | B48: =ChugachRAW!A48 -> 2017 | C48: =ChugachRAW!C48 -> Sport | D48: =ChugachRAW!D48 -> Chum | E48: =ChugachRAW!F48 -> 188.51413 | F48: =ChugachRAW!G48 -> 235.64267 | I48: Subsistence | J48: Chugach | K48: 2012 | N48: 20.1256 | O48: 25.157 | P48: 485.95 | Q48: 523 | T48: 2972.4133 | U48: 6665.1667
A49: Chugach | B49: =ChugachRAW!A49 -> 2018 | C49: =ChugachRAW!C49 -> Sport | D49: =ChugachRAW!D49 -> Chum | E49: =ChugachRAW!F49 -> 184.35307 | F49: =ChugachRAW!G49 -> 230.44133 | I49: Subsistence | J49: Chugach | K49: 2013 | N49: 119.072 | O49: 148.84 | P49: 499.68 | Q49: 611 | T49: 3132.5863 | U49: 7165.988
A50: Chugach | B50: =ChugachRAW!A50 -> 2019 | C50: =ChugachRAW!C50 -> Sport | D50: =ChugachRAW!D50 -> Chum | E50: =ChugachRAW!F50 -> 229.6392 | F50: =ChugachRAW!G50 -> 287.049 | I50: Subsistence | J50: Chugach | K50: 2014 | P50: 673.27 | Q50: 715 | R50: 0.801 | S50: 0.89 | T50: 1359.2948 | U50: 2880.193
A51: Chugach | B51: =ChugachRAW!A51 -> 2020 | C51: =ChugachRAW!C51 -> Sport | D51: =ChugachRAW!D51 -> Chum | E51: =ChugachRAW!F51 -> 72.9696 | F51: =ChugachRAW!G51 -> 91.212 | I51: Subsistence | J51: Chugach | K51: 2015 | N51: 8.4392 | O51: 10.549 | P51: 1009.88 | Q51: 1081 | T51: 1323.6477 | U51: 2778.466
A52: Chugach | B52: =ChugachRAW!A52 -> 2011 | C52: =ChugachRAW!C52 -> Sport | D52: =ChugachRAW!D52 -> Sockeye | E52: =ChugachRAW!F52 -> 1005 | F52: =ChugachRAW!G52 -> 1005 | I52: Subsistence | J52: Chugach | K52: 2016 | L52: 0.17 | M52: 1 | P52: 557.27 | Q52: 558 | T52: 1713.9103 | U52: 3289.3077
A53: Chugach | B53: =ChugachRAW!A53 -> 2012 | C53: =ChugachRAW!C53 -> Sport | D53: =ChugachRAW!D53 -> Sockeye | E53: =ChugachRAW!F53 -> 764 | F53: =ChugachRAW!G53 -> 764 | I53: Subsistence | J53: Chugach | K53: 2017 | L53: 0.34 | M53: 2 | N53: 2.684 | O53: 3.355 | P53: 585.88 | Q53: 624 | R53: 0.44 | S53: 11 | T53: 3220.6761 | U53: 6760.368
A54: Chugach | B54: =ChugachRAW!A54 -> 2013 | C54: =ChugachRAW!C54 -> Sport | D54: =ChugachRAW!D54 -> Sockeye | E54: =ChugachRAW!F54 -> 343 | F54: =ChugachRAW!G54 -> 343 | I54: Subsistence | J54: Chugach | K54: 2018 | N54: 19.738667 | O54: 24.673333 | P54: 449.19 | Q54: 519 | R54: 6.1989 | S54: 12.621 | T54: 4080.8929 | U54: 9106.3087
A55: Chugach | B55: =ChugachRAW!A55 -> 2014 | C55: =ChugachRAW!C55 -> Sport | D55: =ChugachRAW!D55 -> Sockeye | E55: =ChugachRAW!F55 -> 87 | F55: =ChugachRAW!G55 -> 87 | I55: Subsistence | J55: Chugach | K55: 2019 | L55: 1.87 | M55: 11 | N55: 12.0192 | O55: 15.024 | P55: 805.30091 | Q55: 837.251 | R55: 1.9813 | S55: 3.157 | T55: 4568.3303 | U55: 9847.7527
A56: Chugach | B56: =ChugachRAW!A56 -> 2015 | C56: =ChugachRAW!C56 -> Sport | D56: =ChugachRAW!D56 -> Sockeye | E56: =ChugachRAW!F56 -> 155 | F56: =ChugachRAW!G56 -> 155 | I56: Subsistence | J56: Chugach | K56: 2020 | N56: 15.8072 | O56: 19.759 | P56: 507.07732 | Q56: 586.2025 | R56: 22.1253 | S56: 24.583667 | T56: 6183.6608 | U56: 13639.18
A57: Chugach | B57: =ChugachRAW!A57 -> 2016 | C57: =ChugachRAW!C57 -> Sport | D57: =ChugachRAW!D57 -> Sockeye | E57: =ChugachRAW!F57 -> 246 | F57: =ChugachRAW!G57 -> 246 | I57: Subsistence | J57: Tongass | K57: 2011 | L57: 243.55415 | M57: 330.67324 | N57: 88.486956 | O57: 184.00479 | P57: 950.5347 | Q57: 1129.49 | R57: 424.33097 | S57: 780.54 | T57: 15946.769 | U57: 22467.5
...

Sheet ChugachRAW
A1: Year | B1: Area | C1: Fishery | D1: Species | E1: ID | F1: ForestFish_conservative_percent_CNF_Johnson et al 2019 | G1: ForestFish_Liberal_100percentif CNF overlap>0
A2: 2011 | B2: PWS_Area J Saltwater | C2: Sport | D2: Chinook | E2: Chinook_Sport_2011 | F2: 0 | G2: 0 | J2: =SUM(F2:F201)/10 -> 271876.56 | K2: =SUM(G2:G201)/10 -> 500940.99
A3: 2012 | B3: PWS_Area J Saltwater | C3: Sport | D3: Chinook | E3: Chinook_Sport_2012 | F3: 0 | G3: 0
A4: 2013 | B4: PWS_Area J Saltwater | C4: Sport | D4: Chinook | E4: Chinook_Sport_2013 | F4: 0 | G4: 0
A5: 2014 | B5: PWS_Area J Saltwater | C5: Sport | D5: Chinook | E5: Chinook_Sport_2014 | F5: 0 | G5: 0
A6: 2015 | B6: PWS_Area J Saltwater | C6: Sport | D6: Chinook | E6: Chinook_Sport_2015 | F6: 0 | G6: 0
A7: 2016 | B7: PWS_Area J Saltwater | C7: Sport | D7: Chinook | E7: Chinook_Sport_2016 | F7: 0 | G7: 0
A8: 2017 | B8: PWS_Area J Saltwater | C8: Sport | D8: Chinook | E8: Chinook_Sport_2017 | F8: 0 | G8: 0
A9: 2018 | B9: PWS_Area J Saltwater | C9: Sport | D9: Chinook | E9: Chinook_Sport_2018 | F9: 0 | G9: 0
A10: 2019 | B10: PWS_Area J Saltwater | C10: Sport | D10: Chinook | E10: Chinook_Sport_2019 | F10: 0 | G10: 0
A11: 2020 | B11: PWS_Area J Saltwater | C11: Sport | D11: Chinook | E11: Chinook_Sport_2020 | F11: 0 | G11: 0
A12: 2011 | B12: PWS_Area J Saltwater | C12: Sport | D12: Sockeye | E12: Sockeye_Sport_2011 | F12: 362.15125 | G12: 646.69867
A13: 2012 | B13: PWS_Area J Saltwater | C13: Sport | D13: Sockeye | E13: Sockeye_Sport_2012 | F13: 396.83485 | G13: 708.63367
A14: 2013 | B14: PWS_Area J Saltwater | C14: Sport | D14: Sockeye | E14: Sockeye_Sport_2013 | F14: 305.00139 | G14: 544.64533
... A301: 2020 | B301: UCR_PWS_Kenai | C301: Personal use | D301: Chinook | E301: Chinook_Personal use_2020 | F301: 3.91 | G301: 23

Sheet TongassRAW
A1: Line | B1: Year | C1: Fishery | D1: Species | E1: ID | F1: Harvest_total | G1: Proportion_hatchery | H1: Outside_fish_harvest_conservative | I1: Outside_fish_harvest_liberal | J1: Forest_fish_conservative | K1: Forest_fish_liberal
A2: 1 | B2: 2011 | C2: Personal use | D2: Chinook | E2: Chinook_2011_PU | F2: 54 | G2: 0.92592593 | H2: 26.635999 | I2: 1 | J2: 2.026963 | K2: 3.9259259
A3: 4 | B3: 2012 | C3: Personal use | D3: Chinook | E3: Chinook_2012_PU | F3: 39 | G3: 0.92307692 | H3: 17.922481 | I3: 0 | J3: 1.6213476 | K3: 3
A4: 7 | B4: 2013 | C4: Personal use | D4: Chinook | E4: Chinook_2013_PU | F4: 36 | G4: 0 | H4: 17.754868 | I4: 7 | J4: 18.245132 | K4: 29
A5: 10 | B5: 2014 | C5: Personal use | D5: Chinook | E5: Chinook_2014_PU | F5: 43 | G5: 0 | H5: 26.875351 | I5: 16 | J5: 16.124649 | K5: 27
A6: 13 | B6: 2015 | C6: Personal use | D6: Chinook | E6: Chinook_2015_PU | F6: 42 | G6: 0 | H6: 16.783616 | I6: 1 | J6: 25.216384 | K6: 41
A7: 16 | B7: 2016 | C7: Personal use | D7: Chinook | E7: Chinook_2016_PU | F7: 57 | G7: 0 | H7: 29.455229 | I7: 0 | J7: 27.544771 | K7: 57
A8: 19 | B8: 2017 | C8: Personal use | D8: Chinook | E8: Chinook_2017_PU | F8: 2 | G8: 0 | H8: 0.88870756 | I8: 0 | J8: 1.1112924 | K8: 2
A9: 22 | B9: 2018 | C9: Personal use | D9: Chinook | E9: Chinook_2018_PU | F9: 51 | G9: 0 | H9: 42.963801 | I9: 27 | J9: 8.0361992 | K9: 24
A10: 25 | B10: 2019 | C10: Personal use | D10: Chinook | E10: Chinook_2019_PU | F10: 91 | G10: 0 | H10: 73.680984 | I10: 2 | J10: 17.319016 | K10: 89
A11: 28 | B11: 2020 | C11: Personal use | D11: Chinook | E11: Chinook_2020_PU | F11: 35 | G11: 0 | H11: 22.532288 | I11: 7.7 | J11: 12.467712 | K11: 27.3
A12: 31 | B12: 2011 | C12: Personal use | D12: Chum | E12: Chum_2011_PU | F12: 278 | G12: 0 | H12: 14.129626 | I12: 0 | J12: 263.87037 | K12: 278
A13: 34 | B13: 2012 | C13: Personal use | D13: Chum | E13: Chum_2012_PU | F13: 310 | G13: 0 | H13: 14.379312 | I13: 0 | J13: 295.62069 | K13: 310
... A151: 150 | B151: 2020 | C151: Subsistence | D151: Sockeye | E151: Sockeye_2020_subsistence | F151: 20323 | G151: 0.036362742 | H151: 13015.453 | I151: 7638.9 | J151: 7041.8241 | K151: 12222.871

Sheet Commercial exvessel
A1: Year | B1: Area | C1: Forest | D1: Species Name | E1: Number Of Fish (estimated) | F1: Whole Weight (lbs) | G1: Weight/fish (lbs) | H1: Price/pound | I1: Proportion Forest | J1: Forest Fish | K1: Forest Weight (lbs) | L1: Total exvessel $ | N1: Row Labels | O1: Sum of Total exvessel $ | P1: CPI | Q1: CPI Corrected $
A2: 2011 | B2: Cook Inlet | C2: Chugach | D2: Chinook Salmon | E2: 11109 | F2: 225659.85 | G2: =F2/E2 -> 20.313246 | H2: 3.0915141 | I2: 0.52 | J2: =E2*I2 -> 5776.68 | K2: =F2*I2 -> 117343.12 | L2: =K2*H2 -> 362767.92 | N2: 2011 | O2: 1.5402663e+08 | P2: 1.44 | Q2: =GETPIVOTDATA("Total exvessel $",$N$1,"Year","2011")*P2 -> 2.2179835e+08
A3: 2012 | B3: Cook Inlet | C3: Chugach | D3: Chinook Salmon | E3: 2547 | F3: 43282.89 | G3: =F3/E3 -> 16.993675 | H3: 3.3805517 | I3: 0.52 | J3: =E3*I3 -> 1324.44 | K3: =F3*I3 -> 22507.103 | L3: =K3*H3 -> 76086.425 | N3: 2012 | O3: 91387475 | P3: 1.4 | Q3: =GETPIVOTDATA("Total exvessel $",$N$1,"Year","2012")*P3 -> 1.2794247e+08
A4: 2013 | B4: Cook Inlet | C4: Chugach | D4: Chinook Salmon | E4: 5490 | F4: 75992 | G4: =F4/E4 -> 13.841894 | H4: 3.7200142 | I4: 0.52 | J4: =E4*I4 -> 2854.8 | K4: =F4*I4 -> 39515.84 | L4: =K4*H4 -> 146999.48 | N4: 2013 | O4: 2.0044267e+08 | P4: 1.38 | Q4: =GETPIVOTDATA("Total exvessel $",$N$1,"Year","2013")*P4 -> 2.7661088e+08
A5: 2014 | B5: Cook Inlet | C5: Chugach | D5: Chinook Salmon | E5: 4694 | F5: 73856.75 | G5: =F5/E5 -> 15.734288 | H5: 3.7457522 | I5: 0.52 | J5: =E5*I5 -> 2440.88 | K5: =F5*I5 -> 38405.51 | L5: =K5*H5 -> 143857.52 | N5: 2014 | O5: 1.0025997e+08 | P5: 1.36 | Q5: =GETPIVOTDATA("Total exvessel $",$N$1,"Year","2014")*P5 -> 1.3635355e+08
A6: 2015 | B6: Cook Inlet | C6: Chugach | D6: Chinook Salmon | E6: 10841 | F6: 181727.64 | G6: =F6/E6 -> 16.762996 | H6: 2.8952416 | I6: 0.52 | J6: =E6*I6 -> 5637.32 | K6: =F6*I6 -> 94498.373 | L6: =K6*H6 -> 273595.62 | N6: 2015 | O6: 73070456 | P6: 1.36 | Q6: =GETPIVOTDATA("Total exvessel $",$N$1,"Year","2015")*P6 -> 99375821
A7: 2016 | B7: Cook Inlet | C7: Chugach | D7: Chinook Salmon | E7: 10503 | F7: 191874.99 | G7: =F7/E7 -> 18.268589 | H7: 3.0380938 | I7: 0.52 | J7: =E7*I7 -> 5461.56 | K7: =F7*I7 -> 99774.995 | L7: =K7*H7 -> 303125.79 | N7: 2016 | O7: 68417035 | P7: 1.34 | Q7: =GETPIVOTDATA("Total exvessel $",$N$1,"Year","2016")*P7 -> 91678827
A8: 2017 | B8: Cook Inlet | C8: Chugach | D8: Chinook Salmon | E8: 8030 | F8: 175033.84 | G8: =F8/E8 -> 21.797489 | H8: 3.8601404 | I8: 0.52 | J8: =E8*I8 -> 4175.6 | K8: =F8*I8 -> 91017.597 | L8: =K8*H8 -> 351340.7 | N8: 2017 | O8: 1.1525519e+08 | P8: 1.31 | Q8: =GETPIVOTDATA("Total exvessel $",$N$1,"Year","2017")*P8 -> 1.509843e+08
A9: 2018 | B9: Cook Inlet | C9: Chugach | D9: Chinook Salmon | E9: 3534 | F9: 48656.937 | G9: =F9/E9 -> 13.768233 | H9: 3.5624842 | I9: 0.52 | J9: =E9*I9 -> 1837.68 | K9: =F9*I9 -> 25301.607 | L9: =K9*H9 -> 90136.576 | N9: 2018 | O9: 68875865 | P9: 1.28 | Q9: =GETPIVOTDATA("Total exvessel $",$N$1,"Year","2018")*P9 -> 88161107
A10: 2019 | B10: Cook Inlet | C10: Chugach | D10: Chinook Salmon | E10: 3625 | F10: 57269.317 | G10: =F10/E10 -> 15.798432 | H10: 3.5843577 | I10: 0.52 | J10: =E10*I10 -> 1885 | K10: =F10*I10 -> 29780.045 | L10: =K10*H10 -> 106742.33 | N10: 2019 | O10: 72840230 | P10: 1.26 | Q10: =GETPIVOTDATA("Total exvessel $",$N$1,"Year","2019")*P10 -> 91778690
A11: 2020 | B11: Cook Inlet | C11: Chugach | D11: Chinook Salmon | E11: 3310 | F11: 41565.654 | G11: =F11/E11 -> 12.557599 | H11: 4.3285878 | I11: 0.52 | J11: =E11*I11 -> 1721.2 | K11: =F11*I11 -> 21614.14 | L11: =K11*H11 -> 93558.701 | N11: 2020 | O11: 35702899 | P11: 1.23 | Q11: =GETPIVOTDATA("Total exvessel $",$N$1,"Year","2020")*P11 -> 43914566
A12: 2011 | B12: Cook Inlet | C12: Chugach | D12: Chum Salmon | E12: 160871 | F12: 1073335 | G12: =F12/E12 -> 6.6720229 | H12: 0.70105297 | I12: 0.08 | J12: =E12*I12 -> 12869.68 | K12: =F12*I12 -> 85866.8 | L12: =K12*H12 -> 60197.175 | N12: (blank)
A13: 2012 | B13: Cook Inlet | C13: Chugach | D13: Chum Salmon | E13: 326199 | F13: 2634416.7 | G13: =F13/E13 -> 8.0761031 | H13: 0.51098547 | I13: 0.08 | J13: =E13*I13 -> 26095.92 | K13: =F13*I13 -> 210753.34 | L13: =K13*H13 -> 107691.89 | N13: Grand Total | O13: 9.8027842e+08
A14: 2013 | B14: Cook Inlet | C14: Chugach | D14: Chum Salmon | E14: 193714 | F14: 1439556 | G14: =F14/E14 -> 7.4313472 | H14: 0.49659162 | I14: 0.08 | J14: =E14*I14 -> 15497.12 | K14: =F14*I14 -> 115164.48 | L14: =K14*H14 -> 57189.716
A15: 2014 | B15: Cook Inlet | C15: Chugach | D15: Chum Salmon | E15: 189914 | F15: 1397873.7 | G15: =F15/E15 -> 7.3605614 | H15: 0.56377466 | I15: 0.08 | J15: =E15*I15 -> 15193.12 | K15: =F15*I15 -> 111829.89 | L15: =K15*H15 -> 63046.859 | N15: Average Exvessel Price | O15: =AVERAGE(O2:O11) -> 98027842 | Q15: =AVERAGE(Q2:Q11) -> 1.3285986e+08
A16: 2015 | B16: Cook Inlet | C16: Chugach | D16: Chum Salmon | E16: 387874 | F16: 2548438.5 | G16: =F16/E16 -> 6.570274 | H16: 0.43688313 | I16: 0.08 | J16: =E16*I16 -> 31029.92 | K16: =F16*I16 -> 203875.08 | L16: =K16*H16 -> 89069.581
A17: 2016 | B17: Cook Inlet | C17: Chugach | D17: Chum Salmon | E17: 197238 | F17: 1382633.6 | G17: =F17/E17 -> 7.0099758 | H17: 0.37787008 | I17: 0.08 | J17: =E17*I17 -> 15779.04 | K17: =F17*I17 -> 110610.69 | L17: =K17*H17 -> 41796.469 | N17: Average of Weight/fish (lbs) | O17: Column Labels
A18: 2017 | B18: Cook Inlet | C18: Chugach | D18: Chum Salmon | E18: 441826 | F18: 3545701.3 | G18: =F18/E18 -> 8.0251079 | H18: 0.62588999 | I18: 0.08 | J18: =E18*I18 -> 35346.08 | K18: =F18*I18 -> 283656.11 | L18: =K18*H18 -> 177537.52 | N18: Row Labels | O18: Chinook Salmon | P18: Chum Salmon | Q18: Coho Salmon | R18: Pink Salmon | S18: Sockeye Salmon | T18: (blank) | U18: Grand Total
A19: 2018 | B19: Cook Inlet | C19: Chugach | D19: Chum Salmon | E19: 164117 | F19: 1369231.9 | G19: =F19/E19 -> 8.3430232 | H19: 0.71547359 | I19: 0.08 | J19: =E19*I19 -> 13129.36 | K19: =F19*I19 -> 109538.56 | L19: =K19*H19 -> 78371.944 | N19: Chugach | O19: 17.42278 | P19: 7.3379182 | Q19: 7.1025962 | R19: 3.4894605 | S19: 5.6656407 | U19: 8.2036791
A20: 2019 | B20: Cook Inlet | C20: Chugach | D20: Chum Salmon | E20: 185470 | F20: 1281013.5 | G20: =F20/E20 -> 6.90685 | H20: 0.42393966 | I20: 0.08 | J20: =E20*I20 -> 14837.6 | K20: =F20*I20 -> 102481.08 | L20: =K20*H20 -> 43445.793 | N20: Tongass | O20: 13.877959 | P20: 8.2144153 | Q20: 6.9667653 | R20: 3.6388193 | S20: 5.7277995 | U20: 7.6851516
A21: 2020 | B21: Cook Inlet | C21: Chugach | D21: Chum Salmon | E21: 45836 | F21: 366161.21 | G21: =F21/E21 -> 7.9885071 | H21: 0.47976855 | I21: 0.08 | J21: =E21*I21 -> 3666.88 | K21: =F21*I21 -> 29292.897 | L21: =K21*H21 -> 14053.811 | N21: (blank)
A22: 2011 | B22: Cook Inlet | C22: Chugach | D22: Coho Salmon | E22: 95625 | F22: 547096.8 | G22: =F22/E22 -> 5.7212737 | H22: 0.78163846 | I22: 0.64 | J22: =E22*I22 -> 61200 | K22: =F22*I22 -> 350141.95 | L22: =K22*H22 -> 273684.42 | N22: Grand Total | O22: 16.241173 | P22: 7.6300839 | Q22: 7.0573192 | R22: 3.5392468 | S22: 5.6863603 | U22: 8.0308366
A23: 2012 | B23: Cook Inlet | C23: Chugach | D23: Coho Salmon | E23: 107419 | F23: 647523.33 | G23: =F23/E23 -> 6.0280149 | H23: 0.75789172 | I23: 0.64 | J23: =E23*I23 -> 68748.16 | K23: =F23*I23 -> 414414.93 | L23: =K23*H23 -> 314081.65
A24: 2013 | B24: Cook Inlet | C24: Chugach | D24: Coho Salmon | E24: 266802 | F24: 1641448 | G24: =F24/E24 -> 6.1523077 | H24: 0.98659099 | I24: 0.64 | J24: =E24*I24 -> 170753.28 | K24: =F24*I24 -> 1050526.7 | L24: =K24*H24 -> 1036440.2
A25: 2014 | B25: Cook Inlet | C25: Chugach | D25: Coho Salmon | E25: 136879 | F25: 865132.78 | G25: =F25/E25 -> 6.32042 | H25: 0.84542769 | I25: 0.64 | J25: =E25*I25 -> 87602.56 | K25: =F25*I25 -> 553684.98 | L25: =K25*H25 -> 468100.61
A26: 2015 | B26: Cook Inlet | C26: Chugach | D26: Coho Salmon | E26: 218653 | F26: 1284124.8 | G26: =F26/E26 -> 5.8728889 | H26: 0.64896856 | I26: 0.64 | J26: =E26*I26 -> 139937.92 | K26: =F26*I26 -> 821839.86 | L26: =K26*H26 -> 533348.23
A27: 2016 | B27: Cook Inlet | C27: Chugach | D27: Coho Salmon | E27: 147140 | F27: 933542.01 | G27: =F27/E27 -> 6.3445835 | H27: 0.77642713 | I27: 0.64 | J27: =E27*I27 -> 94169.6 | K27: =F27*I27 -> 597466.89 | L27: =K27*H27 -> 463889.5
A28: 2017 | B28: Cook Inlet | C28: Chugach | D28: Coho Salmon | E28: 315972 | F28: 1987441.7 | G28: =F28/E28 -> 6.2899299 | H28: 1.0555389 | I28: 0.64 | J28: =E28*I28 -> 202222.08 | K28: =F28*I28 -> 1271962.7 | L28: =K28*H28 -> 1342606.1
A29: 2018 | B29: Cook Inlet | C29: Chugach | D29: Coho Salmon | E29: 246299 | F29: 1589741 | G29: =F29/E29 -> 6.4545166 | H29: 1.0210586 | I29: 0.64 | J29: =E29*I29 -> 157631.36 | K29: =F29*I29 -> 1017434.2 | L29: =K29*H29 -> 1038860
A30: 2019 | B30: Cook Inlet | C30: Chugach | D30: Coho Salmon | E30: 174850 | F30: 1017967.6 | G30: =F30/E30 -> 5.821948 | H30: 0.9202445 | I30: 0.64 | J30: =E30*I30 -> 111904 | K30: =F30*I30 -> 651499.27 | L30: =K30*H30 -> 599538.62
A31: 2020 | B31: Cook Inlet | C31: Chugach | D31: Coho Salmon | E31: 141446 | F31: 847644.44 | G31: =F31/E31 -> 5.9927071 | H31: 0.99361586 | I31: 0.64 | J31: =E31*I31 -> 90525.44 | K31: =F31*I31 -> 542492.44 | L31: =K31*H31 -> 539029.1
A32: 2011 | B32: Cook Inlet | C32: Chugach | D32: Pink Salmon | E32: 395951 | F32: 1151542 | G32: =F32/E32 -> 2.9082942 | H32: 0.41623871 | I32: 0.14 | J32: =E32*I32 -> 55433.14 | K32: =F32*I32 -> 161215.88 | L32: =K32*H32 -> 67104.289
A33: 2012 | B33: Cook Inlet | C33: Chugach | D33: Pink Salmon | E33: 726064 | F33: 2595190 | G33: =F33/E33 -> 3.5743268 | H33: 0.32478389 | I33: 0.14 | J33: =E33*I33 -> 101648.96 | K33: =F33*I33 -> 363326.6 | L33: =K33*H33 -> 118002.63
A34: 2013 | B34: Cook Inlet | C34: Chugach | D34: Pink Salmon | E34: 2146679 | F34: 6616113 | G34: =F34/E34 -> 3.0820225 | H34: 0.38858936 | I34: 0.14 | J34: =E34*I34 -> 300535.06 | K34: =F34*I34 -> 926255.82 | L34: =K34*H34 -> 359933.16
... A151: 2020 | B151: Southeast/Yakutat | C151: Tongass | D151: Sockeye Salmon | E151: 453021 | F151: 2342837.5 | G151: =F151/E151 -> 5.171587 | H151: 1.6497337 | I151: 0.29 | J151: =E151*I151 -> 131376.09 | K151: =F151*I151 -> 679422.88 | L151: =K151*H151 -> 1120866.8

Sheet commercial_cpi
A1: Year | B1: CPI
A2: 2011 | B2: 1.44
A3: 2012 | B3: 1.4
A4: 2013 | B4: 1.38
A5: 2014 | B5: 1.36
A6: 2015 | B6: 1.36
A7: 2016 | B7: 1.34
A8: 2017 | B8: 1.31
A9: 2018 | B9: 1.28
A10: 2019 | B10: 1.26
A11: 2020 | B11: 1.23

Sheet Commercial
A1: Forest | B1: Species Name | C1: Year | D1: Sum of Number Of Fish (estimated) | E1: Sum of Whole Weight (lbs) | F1: Weight/fish (lbs) | G1: Proportion Forest | H1: # Forest Fish | I1: #ForestMass(lbs) | J1: Recovery Rate | K1: Avg Servings (6oz) | M1: % forest fish | P1: Number and % by species | T1: Number of Fish Per Year | W1: Number of Servings
A2: Chugach | B2: Chinook Salmon | C2: 2011 | D2: 30222 | E2: 620626.84 | F2: =E2/D2 -> 20.535598 | G2: 0.52 | H2: =D2*G2 -> 15715.44 | I2: =E2*G2 -> 322725.96 | J2: 0.55 | K2: =(I2*J2)/(6/16) -> 473331.4 | M2: Total catch | N2: =SUM(D2:D101) -> 1.0404546e+09 | P2: Row Labels | Q2: Sum of # Forest Fish | R2: % by species | T2: Row Labels | U2: Sum of # Forest Fish | W2: Row Labels | X2: Sum of Avg Servings (6oz)
A3: Chugach | B3: Chinook Salmon | C3: 2012 | D3: 14764 | E3: 303180.77 | F3: =E3/D3 -> 20.535137 | G3: {=G2} -> 0.52 | H3: =D3*G3 -> 7677.28 | I3: =E3*G3 -> 157654 | J3: 0.55 | K3: =(I3*J3)/(6/16) -> 231225.87 | M3: Forest catch | N3: =SUM(H2:H101) -> 4.4718694e+08 | P3: Chinook Salmon | Q3: 293803.56 | R3: =GETPIVOTDATA("# Forest Fish",$P$2,"Species Name","Chinook Salmon")/GETPIVOTDATA("# Forest Fish",$P$2)*100 -> 0.065700389 | T3: 2011 | U3: 68008573 | W3: 2011 | X3: 3.7405218e+08
A4: Chugach | B4: Chinook Salmon | C4: 2013 | D4: 15669 | E4: 260837.62 | F4: =E4/D4 -> 16.646731 | G4: 0.52 | H4: =D4*G4 -> 8147.88 | I4: =E4*G4 -> 135635.56 | J4: 0.55 | K4: =(I4*J4)/(6/16) -> 198932.16 | M4: % forest | N4: =N3/N2*100 -> 42.979959 | P4: Chum Salmon | Q4: 19852624 | R4: =GETPIVOTDATA("# Forest Fish",$P$2,"Species Name","Chum Salmon")/GETPIVOTDATA("# Forest Fish",$P$2)*100 -> 4.4394463 | T4: 2012 | U4: 30007942 | W4: 2012 | X4: 1.874733e+08
A5: Chugach | B5: Chinook Salmon | C5: 2014 | D5: 15531 | E5: 267525.01 | F5: =E5/D5 -> 17.225228 | G5: 0.52 | H5: =D5*G5 -> 8076.12 | I5: =E5*G5 -> 139113.01 | J5: 0.55 | K5: =(I5*J5)/(6/16) -> 204032.41 | P5: Coho Salmon | Q5: 20489778 | R5: =GETPIVOTDATA("# Forest Fish",$P$2,"Species Name","Coho Salmon")/GETPIVOTDATA("# Forest Fish",$P$2)*100 -> 4.5819267 | T5: 2013 | U5: 1.127784e+08 | W5: 2013 | X5: 5.3744682e+08
A6: Chugach | B6: Chinook Salmon | C6: 2015 | D6: 34194 | E6: 589024.35 | F6: =E6/D6 -> 17.225956 | G6: 0.52 | H6: =D6*G6 -> 17780.88 | I6: =E6*G6 -> 306292.66 | J6: 0.55 | K6: =(I6*J6)/(6/16) -> 449229.24 | M6: Total State Salmon Catch | P6: Pink Salmon | Q6: 3.9737056e+08 | R6: =GETPIVOTDATA("# Forest Fish",$P$2,"Species Name","Pink Salmon")/GETPIVOTDATA("# Forest Fish",$P$2)*100 -> 88.860054 | T6: 2014 | U6: 48420061 | W6: 2014 | X6: 2.7260034e+08
A7: Chugach | B7: Chinook Salmon | C7: 2016 | D7: 23192 | E7: 420544.52 | F7: =E7/D7 -> 18.133172 | G7: 0.52 | H7: =D7*G7 -> 12059.84 | I7: =E7*G7 -> 218683.15 | J7: 0.55 | K7: =(I7*J7)/(6/16) -> 320735.29 | M7: Year | N7: Number of Fish | P7: Sockeye Salmon | Q7: 9180176.3 | R7: =GETPIVOTDATA("# Forest Fish",$P$2,"Species Name","Sockeye Salmon")/GETPIVOTDATA("# Forest Fish",$P$2)*100 -> 2.0528722 | T7: 2015 | U7: 54173018 | W7: 2015 | X7: 2.9818021e+08
A8: Chugach | B8: Chinook Salmon | C8: 2017 | D8: 22400 | E8: 471913.78 | F8: =E8/D8 -> 21.067579 | G8: 0.52 | H8: =D8*G8 -> 11648 | I8: =E8*G8 -> 245395.16 | J8: 0.55 | K8: =(I8*J8)/(6/16) -> 359912.91 | M8: 2020 | N8: 116812649 | P8: Grand Total | Q8: 4.4718694e+08 | R8: =SUM(R3:R7) -> 100 | T8: 2016 | U8: 24772014 | W8: 2016 | X8: 1.6391939e+08
A9: Chugach | B9: Chinook Salmon | C9: 2018 | D9: 11937 | E9: 185792.48 | F9: =E9/D9 -> 15.56442 | G9: 0.52 | H9: =D9*G9 -> 6207.24 | I9: =E9*G9 -> 96612.092 | J9: 0.55 | K9: =(I9*J9)/(6/16) -> 141697.74 | M9: 2019 | N9: 204359949 | T9: 2017 | U9: 46848004 | W9: 2017 | X9: 2.7437398e+08
A10: Chugach | B10: Chinook Salmon | C10: 2019 | D10: 23367 | E10: 427114.34 | F10: =E10/D10 -> 18.278527 | G10: 0.52 | H10: =D10*G10 -> 12150.84 | I10: =E10*G10 -> 222099.45 | J10: 0.55 | K10: =(I10*J10)/(6/16) -> 325745.87 | M10: 2018 | N10: 113824027 | T10: 2018 | U10: 15863084 | W10: 2018 | X10: 1.1478108e+08
A11: Chugach | B11: Chinook Salmon | C11: 2020 | D11: 10188 | E11: 134246.19 | F11: =E11/D11 -> 13.176894 | G11: 0.52 | H11: =D11*G11 -> 5297.76 | I11: =E11*G11 -> 69808.02 | J11: 0.55 | K11: =(I11*J11)/(6/16) -> 102385.1 | M11: 2017 | N11: 222838278 | T11: 2019 | U11: 32386230 | W11: 2019 | X11: 1.9000917e+08
A12: Chugach | B12: Chum Salmon | C12: 2011 | D12: 2075061 | E12: 15242710 | F12: =E12/D12 -> 7.3456682 | G12: 0.08 | H12: =D12*G12 -> 166004.88 | I12: =E12*G12 -> 1219416.8 | J12: 0.6 | K12: =(I12*J12)/(6/16) -> 1951066.8 | M12: 2016 | N12: 111236964 | T12: 2020 | U12: 13929623 | W12: 2020 | X12: 82524071
A13: Chugach | B13: Chum Salmon | C13: 2012 | D13: 4143735 | E13: 29831634 | F13: =E13/D13 -> 7.1992138 | G13: 0.08 | H13: =D13*G13 -> 331498.8 | I13: =E13*G13 -> 2386530.8 | J13: 0.6 | K13: =(I13*J13)/(6/16) -> 3818449.2 | M13: 2015 | N13: 265118099 | P13: Number and % by Forest | T13: (blank) | W13: (blank)
A14: Chugach | B14: Chum Salmon | C14: 2013 | D14: 4264105 | E14: 31773037 | F14: =E14/D14 -> 7.4512792 | G14: 0.08 | H14: =D14*G14 -> 341128.4 | I14: =E14*G14 -> 2541842.9 | J14: 0.6 | K14: =(I14*J14)/(6/16) -> 4066948.7 | M14: 2014 | N14: 156429264 | P14: Row Labels | Q14: Sum of # Forest Fish | R14: % by forest | T14: Grand Total | U14: 4.4718694e+08 | W14: Average # servings | X14: =AVERAGE(X3:X12) -> 2.4953605e+08
A15: Chugach | B15: Chum Salmon | C15: 2014 | D15: 1706745 | E15: 13021968 | F15: =E15/D15 -> 7.629709 | G15: 0.08 | H15: =D15*G15 -> 136539.6 | I15: =E15*G15 -> 1041757.4 | J15: 0.6 | K15: =(I15*J15)/(6/16) -> 1666811.9 | M15: 2013 | N15: 280323323 | P15: Chugach | Q15: 79179876 | R15: =GETPIVOTDATA("# Forest Fish",$P$14,"Forest","Chugach")/GETPIVOTDATA("# Forest Fish",$P$14)*100 -> 17.706214 | W15: Number of lbs | X15: =X14*(6/16) -> 93576020
A16: Chugach | B16: Chum Salmon | C16: 2015 | D16: 2900187 | E16: 18080004 | F16: =E16/D16 -> 6.2340822 | G16: 0.08 | H16: =D16*G16 -> 232014.96 | I16: =E16*G16 -> 1446400.3 | J16: 0.6 | K16: =(I16*J16)/(6/16) -> 2314240.5 | M16: 2012 | N16: 127249924 | P16: Tongass | Q16: 3.6800707e+08 | R16: =GETPIVOTDATA("# Forest Fish",$P$14,"Forest","Tongass")/GETPIVOTDATA("# Forest Fish",$P$14)*100 -> 82.293786
A17: Chugach | B17: Chum Salmon | C17: 2016 | D17: 3368157 | E17: 23474819 | F17: =E17/D17 -> 6.9696332 | G17: 0.08 | H17: =D17*G17 -> 269452.56 | I17: =E17*G17 -> 1877985.5 | J17: 0.6 | K17: =(I17*J17)/(6/16) -> 3004776.8 | M17: 2011 | N17: 177214215 | P17: (blank)
A18: Chugach | B18: Chum Salmon | C18: 2017 | D18: 5832649 | E18: 44290753 | F18: =E18/D18 -> 7.5935914 | G18: 0.08 | H18: =D18*G18 -> 466611.92 | I18: =E18*G18 -> 3543260.2 | J18: 0.6 | K18: =(I18*J18)/(6/16) -> 5669216.4 | M18: Total State Catch | N18: =SUM(N8:N17) -> 1775406692 | P18: Grand Total | Q18: 4.4718694e+08
A19: Chugach | B19: Chum Salmon | C19: 2018 | D19: 3632471 | E19: 30344027 | F19: =E19/D19 -> 8.3535497 | G19: 0.08 | H19: =D19*G19 -> 290597.68 | I19: =E19*G19 -> 2427522.1 | J19: 0.6 | K19: =(I19*J19)/(6/16) -> 3884035.4 | M19: % Forest | N19: =N3/N18 -> 0.2518786
A20: Chugach | B20: Chum Salmon | C20: 2019 | D20: 5566420 | E20: 34626290 | F20: =E20/D20 -> 6.2205673 | G20: 0.08 | H20: =D20*G20 -> 445313.6 | I20: =E20*G20 -> 2770103.2 | J20: 0.6 | K20: =(I20*J20)/(6/16) -> 4432165.2
A21: Chugach | B21: Chum Salmon | C21: 2020 | D21: 2062606 | E21: 15439300 | F21: =E21/D21 -> 7.4853365 | G21: 0.08 | H21: =D21*G21 -> 165008.48 | I21: =E21*G21 -> 1235144 | J21: 0.6 | K21: =(I21*J21)/(6/16) -> 1976230.4
A22: Chugach | B22: Coho Salmon | C22: 2011 | D22: 465955 | E22: 3188543.2 | F22: =E22/D22 -> 6.8430283 | G22: 0.64 | H22: =D22*G22 -> 298211.2 | I22: =E22*G22 -> 2040667.7 | J22: 0.57 | K22: =(I22*J22)/(6/16) -> 3101814.9
A23: Chugach | B23: Coho Salmon | C23: 2012 | D23: 316579 | E23: 2350273.6 | F23: =E23/D23 -> 7.4239717 | G23: 0.64 | H23: =D23*G23 -> 202610.56 | I23: =E23*G23 -> 1504175.1 | J23: 0.57 | K23: =(I23*J23)/(6/16) -> 2286346.1
A24: Chugach | B24: Coho Salmon | C24: 2013 | D24: 886027 | E24: 6569246.7 | F24: =E24/D24 -> 7.4142737 | G24: 0.64 | H24: =D24*G24 -> 567057.28 | I24: =E24*G24 -> 4204317.9 | J24: 0.57 | K24: =(I24*J24)/(6/16) -> 6390563.2
A25: Chugach | B25: Coho Salmon | C25: 2014 | D25: 751083 | E25: 5835139.6 | F25: =E25/D25 -> 7.7689677 | G25: 0.64 | H25: =D25*G25 -> 480693.12 | I25: =E25*G25 -> 3734489.3 | J25: 0.57 | K25: =(I25*J25)/(6/16) -> 5676423.8
A26: Chugach | B26: Coho Salmon | C26: 2015 | D26: 442106 | E26: 2871770.7 | F26: =E26/D26 -> 6.495661 | G26: 0.64 | H26: =D26*G26 -> 282947.84 | I26: =E26*G26 -> 1837933.3 | J26: 0.57 | K26: =(I26*J26)/(6/16) -> 2793658.5
A27: Chugach | B27: Coho Salmon | C27: 2016 | D27: 629415 | E27: 5356469.1 | F27: =E27/D27 -> 8.5102342 | G27: 0.64 | H27: =D27*G27 -> 402825.6 | I27: =E27*G27 -> 3428140.2 | J27: 0.57 | K27: =(I27*J27)/(6/16) -> 5210773.1
A28: Chugach | B28: Coho Salmon | C28: 2017 | D28: 872302 | E28: 6552311.3 | F28: =E28/D28 -> 7.511517 | G28: 0.64 | H28: =D28*G28 -> 558273.28 | I28: =E28*G28 -> 4193479.3 | J28: 0.57 | K28: =(I28*J28)/(6/16) -> 6374088.5
A29: Chugach | B29: Coho Salmon | C29: 2018 | D29: 769089 | E29: 6177614.9 | F29: =E29/D29 -> 8.0323797 | G29: 0.64 | H29: =D29*G29 -> 492216.96 | I29: =E29*G29 -> 3953673.5 | J29: 0.57 | K29: =(I29*J29)/(6/16) -> 6009583.8
A30: Chugach | B30: Coho Salmon | C30: 2019 | D30: 701182 | E30: 5318938.9 | F30: =E30/D30 -> 7.5856751 | G30: 0.64 | H30: =D30*G30 -> 448756.48 | I30: =E30*G30 -> 3404120.9 | J30: 0.57 | K30: =(I30*J30)/(6/16) -> 5174263.7
A31: Chugach | B31: Coho Salmon | C31: 2020 | D31: 430063 | E31: 3243531.1 | F31: =E31/D31 -> 7.5419907 | G31: 0.64 | H31: =D31*G31 -> 275240.32 | I31: =E31*G31 -> 2075859.9 | J31: 0.57 | K31: =(I31*J31)/(6/16) -> 3155307.1
... A101: Tongass | B101: Sockeye Salmon | C101: 2020 | D101: 453021 | E101: 2342837.5 | F101: =E101/D101 -> 5.171587 | G101: 0.29 | H101: =D101*G101 -> 131376.09 | I101: =E101*G101 -> 679422.88 | J101: 0.53 | K101: =(I101*J101)/(6/16) -> 960251

Sheet Sport
C1: =CombinedRAW!L5 -> Chinook | D1: =CombinedRAW!M5 -> Chinook | E1: =CombinedRAW!N5 -> Chum | F1: =CombinedRAW!O5 -> Chum | G1: =CombinedRAW!P5 -> Coho | H1: =CombinedRAW!Q5 -> Coho | I1: =CombinedRAW!R5 -> Pink | J1: =CombinedRAW!S5 -> Pink | ... L1: =CombinedRAW!U5 -> Sockeye | M1: Totals | R1: % by species | V1: % by Forest
A2: =CombinedRAW!J6 -> Forest | B2: =CombinedRAW!K6 -> Year | C2: Conservative | D2: Liberal | E2: Conservative | F2: Liberal | G2: Conservative | H2: Liberal | I2: Conservative | J2: Liberal | K2: Conservative | L2: Liberal | M2: Total Conservative | N2: Total Liberal | R2: Species | S2: % Cons | T2: % Lib | W2: Conservative | X2: Liberal
A3: Chugach | B3: 2011 | C3: =CombinedRAW!L27 -> 1749.81 | D3: =CombinedRAW!M27 -> 10293 | E3: =CombinedRAW!N27 -> 95.738133 | F3: =CombinedRAW!O27 -> 188.17267 | G3: =CombinedRAW!P27 -> 46602.27 | H3: =CombinedRAW!Q27 -> 87555 | I3: =CombinedRAW!R27 -> 2724.3936 | J3: =CombinedRAW!S27 -> 6254.504 | ... L3: =CombinedRAW!U27 -> 434629.7 | M3: =SUM(C3,E3,G3,I3,K3) -> 291555.76 | N3: =SUM(D3,F3,H3,J3,L3) -> 538920.38 | R3: Chinook | S3: =(C37/M37)*100 -> 3.0646461 | T3: =(D37/N37)*100 -> 2.6234811 | V3: Chugach | W3: =M35/M37 -> 0.49317059 | X3: =N35/N37 -> 0.63761035
A4: Chugach | B4: 2012 | C4: =CombinedRAW!L28 -> 206.04 | D4: =CombinedRAW!M28 -> 1212 | E4: =CombinedRAW!N28 -> 23.728 | F4: =CombinedRAW!O28 -> 382.16 | G4: =CombinedRAW!P28 -> 38631.04 | H4: =CombinedRAW!Q28 -> 68725 | I4: =CombinedRAW!R28 -> 3262.0224 | J4: =CombinedRAW!S28 -> 20284.38 | ... L4: =CombinedRAW!U28 -> 487280.63 | M4: =SUM(C4,E4,G4,I4,K4) -> 305919.21 | N4: =SUM(D4,F4,H4,J4,L4) -> 577884.17 | R4: Chum | S4: =E37/M37*100 -> 1.2979761 | T4: =F37/N37*100 -> 0.95057633 | V4: Tongass | W4: =M36/M37 -> 0.50682941 | X4: =N36/N37 -> 0.36238965
A5: Chugach | B5: 2013 | C5: =CombinedRAW!L29 -> 238.85 | D5: =CombinedRAW!M29 -> 1405 | E5: =CombinedRAW!N29 -> 251.26667 | F5: =CombinedRAW!O29 -> 440.83333 | G5: =CombinedRAW!P29 -> 48919.03 | H5: =CombinedRAW!Q29 -> 92842 | I5: =CombinedRAW!R29 -> 2016.3513 | J5: =CombinedRAW!S29 -> 5114.3903 | ... L5: =CombinedRAW!U29 -> 485197.65 | M5: =SUM(C5,E5,G5,I5,K5) -> 322259.38 | N5: =SUM(D5,F5,H5,J5,L5) -> 584999.87 | R5: Coho | S5: =G37/M37*100 -> 40.536884 | T5: =H37/N37*100 -> 33.807269
A6: Chugach | B6: 2014 | C6: =CombinedRAW!L30 -> 221.17 | D6: =CombinedRAW!M30 -> 1301 | E6: =CombinedRAW!N30 -> 105.984 | F6: =CombinedRAW!O30 -> 158.48 | G6: =CombinedRAW!P30 -> 43593.813 | H6: =CombinedRAW!Q30 -> 93534.152 | I6: =CombinedRAW!R30 -> 4785.5511 | J6: =CombinedRAW!S30 -> 28773.546 | ... L6: =CombinedRAW!U30 -> 415208.14 | M6: =SUM(C6,E6,G6,I6,K6) -> 286869.32 | N6: =SUM(D6,F6,H6,J6,L6) -> 538975.32 | R6: Pink | S6: =I37/M37*100 -> 12.390012 | T6: =J37/N37*100 -> 10.45725 | V6: % from Foreest
A7: Chugach | B7: 2015 | C7: =CombinedRAW!L31 -> 681.53 | D7: =CombinedRAW!M31 -> 4009 | E7: =CombinedRAW!N31 -> 476.92613 | F7: =CombinedRAW!O31 -> 703.15767 | G7: =CombinedRAW!P31 -> 64093.84 | H7: =CombinedRAW!Q31 -> 115981 | I7: =CombinedRAW!R31 -> 6844.0337 | J7: =CombinedRAW!S31 -> 11789.193 | ... L7: =CombinedRAW!U31 -> 411732.11 | M7: =SUM(C7,E7,G7,I7,K7) -> 303657.91 | N7: =SUM(D7,F7,H7,J7,L7) -> 544214.46 | R7: Sockeye | S7: =K37/M37*100 -> 42.710482 | T7: =L37/N37*100 -> 52.161423 | W7: Total Harvest | X7: Forest Harvest | Y7: % From Forest | Z7: Notes
A8: Chugach | B8: 2016 | C8: =CombinedRAW!L32 -> 1449.08 | D8: =CombinedRAW!M32 -> 8524 | E8: =CombinedRAW!N32 -> 148.8184 | F8: =CombinedRAW!O32 -> 729.273 | G8: =CombinedRAW!P32 -> 33630.4 | H8: =CombinedRAW!Q32 -> 65821 | I8: =CombinedRAW!R32 -> 4944.191 | J8: =CombinedRAW!S32 -> 27789.145 | ... L8: =CombinedRAW!U32 -> 354975.33 | M8: =SUM(C8,E8,G8,I8,K8) -> 233537.81 | N8: =SUM(D8,F8,H8,J8,L8) -> 457838.75 | V8: Chugach | W8: 272502 | X8: =SUM(N3:N12)/10 -> 500940.99 | Y8: =X8/W8*100 -> 183.83021 | Z8: total harvest from Haught spreadsheet
A9: Chugach | B9: 2017 | C9: =CombinedRAW!L33 -> 1666.34 | D9: =CombinedRAW!M33 -> 9802 | E9: =CombinedRAW!N33 -> 269.51413 | F9: =CombinedRAW!O33 -> 328.64267 | G9: =CombinedRAW!P33 -> 37422.87 | H9: =CombinedRAW!Q33 -> 79608 | I9: =CombinedRAW!R33 -> 5472.497 | J9: =CombinedRAW!S33 -> 11255.263 | ... L9: =CombinedRAW!U33 -> 329775.86 | M9: =SUM(C9,E9,G9,I9,K9) -> 231582.86 | N9: =SUM(D9,F9,H9,J9,L9) -> 430769.77 | V9: Tongass | W9: =4501817/10 -> 450181.7 | X9: =SUM(N13:N22)/10 -> 284712.81 | Y9: =X9/W9*100 -> 63.243977
A10: Chugach | B10: 2018 | C10: =CombinedRAW!L34 -> 331.67 | D10: =CombinedRAW!M34 -> 1951 | E10: =CombinedRAW!N34 -> 470.35307 | F10: =CombinedRAW!O34 -> 516.44133 | G10: =CombinedRAW!P34 -> 36550.39 | H10: =CombinedRAW!Q34 -> 79177 | I10: =CombinedRAW!R34 -> 5947.248 | J10: =CombinedRAW!S34 -> 25405.52 | ... L10: =CombinedRAW!U34 -> 216196.64 | M10: =SUM(C10,E10,G10,I10,K10) -> 174585.34 | N10: =SUM(D10,F10,H10,J10,L10) -> 323246.6 | V10: Total | W10: =SUM(W8:W9) -> 722683.7 | X10: =SUM(X8:X9) -> 785653.8 | Y10: =X10/W10*100 -> 108.71337
A11: Chugach | B11: 2019 | C11: =CombinedRAW!L35 -> 343.57 | D11: =CombinedRAW!M35 -> 2021 | E11: =CombinedRAW!N35 -> 394.6392 | F11: =CombinedRAW!O35 -> 452.049 | G11: =CombinedRAW!P35 -> 39018.568 | H11: =CombinedRAW!Q35 -> 75589.422 | I11: =CombinedRAW!R35 -> 5252.9678 | J11: =CombinedRAW!S35 -> 11481.875 | ... L11: =CombinedRAW!U35 -> 553758.17 | M11: =SUM(C11,E11,G11,I11,K11) -> 366239.77 | N11: =SUM(D11,F11,H11,J11,L11) -> 643302.51
A12: Chugach | B12: 2020 | C12: =CombinedRAW!L36 -> 229.67 | D12: =CombinedRAW!M36 -> 1351 | E12: =CombinedRAW!N36 -> 137.9696 | F12: =CombinedRAW!O36 -> 156.212 | G12: =CombinedRAW!P36 -> 26256.261 | H12: =CombinedRAW!Q36 -> 50239.51 | I12: =CombinedRAW!R36 -> 6894.8702 | J12: =CombinedRAW!S36 -> 22247.945 | ... L12: =CombinedRAW!U36 -> 295263.45 | M12: =SUM(C12,E12,G12,I12,K12) -> 202558.23 | N12: =SUM(D12,F12,H12,J12,L12) -> 369258.12
A13: Tongass | B13: 2011 | C13: =CombinedRAW!L37 -> 18630.475 | D13: =CombinedRAW!M37 -> 18797.01 | E13: =CombinedRAW!N37 -> 14483.272 | F13: =CombinedRAW!O37 -> 14634.278 | G13: =CombinedRAW!P37 -> 135379.86 | H13: =CombinedRAW!Q37 -> 136931.43 | I13: =CombinedRAW!R37 -> 52051.304 | J13: =CombinedRAW!S37 -> 53771.63 | ... L13: =CombinedRAW!U37 -> 15005.05 | M13: =SUM(C13,E13,G13,I13,K13) -> 234644.64 | N13: =SUM(D13,F13,H13,J13,L13) -> 239139.4
A14: Tongass | B14: 2012 | C14: =CombinedRAW!L38 -> 12855.241 | D14: =CombinedRAW!M38 -> 12870.77 | E14: =CombinedRAW!N38 -> 4337.8767 | F14: =CombinedRAW!O38 -> 4419.5605 | G14: =CombinedRAW!P38 -> 135729.73 | H14: =CombinedRAW!Q38 -> 137538.94 | I14: =CombinedRAW!R38 -> 50305.043 | J14: =CombinedRAW!S38 -> 51743.515 | ... L14: =CombinedRAW!U38 -> 9501 | M14: =SUM(C14,E14,G14,I14,K14) -> 212132.99 | N14: =SUM(D14,F14,H14,J14,L14) -> 216073.79
A15: Tongass | B15: 2013 | C15: =CombinedRAW!L39 -> 12682.13 | D15: =CombinedRAW!M39 -> 12940.747 | E15: =CombinedRAW!N39 -> 15853.122 | F15: =CombinedRAW!O39 -> 16097.193 | G15: =CombinedRAW!P39 -> 191155.57 | H15: =CombinedRAW!Q39 -> 192935.76 | I15: =CombinedRAW!R39 -> 71477.023 | J15: =CombinedRAW!S39 -> 74115.246 | ... L15: =CombinedRAW!U39 -> 13476.2 | M15: =SUM(C15,E15,G15,I15,K15) -> 304239.35 | N15: =SUM(D15,F15,H15,J15,L15) -> 309565.15
A16: Tongass | B16: 2014 | C16: =CombinedRAW!L40 -> 29941.309 | D16: =CombinedRAW!M40 -> 30258.934 | E16: =CombinedRAW!N40 -> 5708.0025 | F16: =CombinedRAW!O40 -> 5932.4694 | G16: =CombinedRAW!P40 -> 281137.32 | H16: =CombinedRAW!Q40 -> 283375.11 | I16: =CombinedRAW!R40 -> 61152.401 | J16: =CombinedRAW!S40 -> 62129.08 | ... L16: =CombinedRAW!U40 -> 16182.75 | M16: =SUM(C16,E16,G16,I16,K16) -> 393195.66 | N16: =SUM(D16,F16,H16,J16,L16) -> 397878.34
A17: Tongass | B17: 2015 | C17: =CombinedRAW!L41 -> 22957.015 | D17: =CombinedRAW!M41 -> 23124.869 | E17: =CombinedRAW!N41 -> 5823.418 | F17: =CombinedRAW!O41 -> 5994.3654 | G17: =CombinedRAW!P41 -> 215609.63 | H17: =CombinedRAW!Q41 -> 219133.75 | I17: =CombinedRAW!R41 -> 73252.308 | J17: =CombinedRAW!S41 -> 74880.81 | ... L17: =CombinedRAW!U41 -> 14105.45 | M17: =SUM(C17,E17,G17,I17,K17) -> 330840.62 | N17: =SUM(D17,F17,H17,J17,L17) -> 337239.25
A18: Tongass | B18: 2016 | C18: =CombinedRAW!L42 -> 21214.056 | D18: =CombinedRAW!M42 -> 21806.163 | E18: =CombinedRAW!N42 -> 6841.2836 | F18: =CombinedRAW!O42 -> 6928.5792 | G18: =CombinedRAW!P42 -> 181604.04 | H18: =CombinedRAW!Q42 -> 184531.95 | I18: =CombinedRAW!R42 -> 78250.355 | J18: =CombinedRAW!S42 -> 79754.67 | ... L18: =CombinedRAW!U42 -> 11210.75 | M18: =SUM(C18,E18,G18,I18,K18) -> 298544.76 | N18: =SUM(D18,F18,H18,J18,L18) -> 304232.11
A19: Tongass | B19: 2017 | C19: =CombinedRAW!L43 -> 16623.658 | D19: =CombinedRAW!M43 -> 16825.082 | E19: =CombinedRAW!N43 -> 3806.9303 | F19: =CombinedRAW!O43 -> 3944.2411 | G19: =CombinedRAW!P43 -> 283894.97 | H19: =CombinedRAW!Q43 -> 286475.92 | I19: =CombinedRAW!R43 -> 73026.357 | J19: =CombinedRAW!S43 -> 75871.33 | ... L19: =CombinedRAW!U43 -> 10457.25 | M19: =SUM(C19,E19,G19,I19,K19) -> 387475.8 | N19: =SUM(D19,F19,H19,J19,L19) -> 393573.82
A20: Tongass | B20: 2018 | C20: =CombinedRAW!L44 -> 7311.6786 | D20: =CombinedRAW!M44 -> 7645.1053 | E20: =CombinedRAW!N44 -> 2033.464 | F20: =CombinedRAW!O44 -> 2069.4091 | G20: =CombinedRAW!P44 -> 129533.52 | H20: =CombinedRAW!Q44 -> 131869.63 | I20: =CombinedRAW!R44 -> 47994.702 | J20: =CombinedRAW!S44 -> 49279.04 | ... L20: =CombinedRAW!U44 -> 7145.35 | M20: =SUM(C20,E20,G20,I20,K20) -> 193877.47 | N20: =SUM(D20,F20,H20,J20,L20) -> 198008.53
A21: Tongass | B21: 2019 | C21: =CombinedRAW!L45 -> 8476.0113 | D21: =CombinedRAW!M45 -> 8694.0869 | E21: =CombinedRAW!N45 -> 6909.5224 | F21: =CombinedRAW!O45 -> 7050.9043 | G21: =CombinedRAW!P45 -> 162723.64 | H21: =CombinedRAW!Q45 -> 167385.53 | I21: =CombinedRAW!R45 -> 79204.337 | J21: =CombinedRAW!S45 -> 80244.44 | ... L21: =CombinedRAW!U45 -> 9839 | M21: =SUM(C21,E21,G21,I21,K21) -> 266487.06 | N21: =SUM(D21,F21,H21,J21,L21) -> 273213.97
